### `以下程序输出什么?为什么?`
题目：
```js
try {
  let a = 0;
  (async function() {
      a += 1
      console.log('inner', a)
      throw new Error('123')
      // a()
  })()
  console.log('outer', a)
} catch(e) {
  console.log('catchError', e)
}
```
解答：
async定义的方法默认一定会返回一个promise，如果一个async函数的返回值看起来不是promise，那么它将会被隐式地包装在一个promise中。所以它内部自动捕获异常，async函数执行中断，并通过隐式返回Promise将错误传递给调用者。
<br>
结果：输出结果 inner 1  outer  1   Error： 123   ，抛出Error后，catch不再执行

### `程序输出顺序`
```js
setTimeout(function(){
  console.log('1')
},0)
async fuction async1(){
  console.log('2')
  await async2();
  console.log('3')
}
async function async2(){
  console.log('4')
}
console.log('5')
async1();
console.log('6');
```
解答：
结果：5 => 2 => 3 => 6 => 4 => 1